Workbook

Sheet Notes
A1: Source: 'Entreprises et marques utilisant le Nutri-Score en France' (PDF, 38 pages). Title page says Avril 2024; the file name says janvier 2024.
A2: Extraction: table cells read from the PDF's own grid lines, so each row of the PDF = one row here. 1,406 table rows found; 1 is completely blank in the PDF (page 25, between NEWREST FRANCE LE BOURGET and NL International France) and was dropped -> 1,405 companies.
A3: Companies sheet: one row per company, brands exactly as written in the PDF (line wraps removed).
A4: Brands sheet: one row per brand, obtained by splitting the brand cell on commas/semicolons (LIDL: on ' - '). Best-effort: a brand name containing a comma would be split wrongly.
A5: Brand count (Companies!D) is a formula counting that company's rows in Brands.
A6: Review flag: rows where the PDF is ambiguous - several legal entities in one cell, empty/placeholder brand ('aucune', 'No name', 'Marque générique', etc.), partial lists ('25 marques concernées. Par exemple...'), or obviously wrong content (e.g. 'Umsatzsteuer-IdNr.').
A7: Values are kept verbatim (typos, capitalisation, duplicates such as 'Val de Luce' appearing twice are NOT corrected).

Sheet Companies
A1: Company ID | B1: Company | C1: Brands (as listed in PDF) | D1: Brand count (split) | E1: PDF page | F1: Review flag
A2: 1 | B2: 100% Ty'bigoud | C2: 100% Ty'bigoud | D2: =COUNTIF(Brands!$A:$A,A2) -> 1 | E2: 1
A3: 2 | B3: 110 GRAINES | C3: 110 Graines | D3: =COUNTIF(Brands!$A:$A,A3) -> 1 | E3: 1
A4: 3 | B4: 3615 soda | C4: Simple Vice | D4: =COUNTIF(Brands!$A:$A,A4) -> 1 | E4: 1
A5: 4 | B5: 4Retail | C5: Zagazoe | D5: =COUNTIF(Brands!$A:$A,A5) -> 1 | E5: 1
A6: 5 | B6: 4ULTRA | C6: 4ULTRA | D6: =COUNTIF(Brands!$A:$A,A6) -> 1 | E6: 1
A7: 6 | B7: 5M DEVELOPMENT | C7: STARTINE | D7: =COUNTIF(Brands!$A:$A,A7) -> 1 | E7: 1
A8: 7 | B8: 77 FOODS | C8: LA VIE | D8: =COUNTIF(Brands!$A:$A,A8) -> 1 | E8: 1
A9: 8 | B9: A&O L'EPICERIE LOCALE | C9: A&O | D9: =COUNTIF(Brands!$A:$A,A9) -> 1 | E9: 1
A10: 9 | B10: A.C.V. FOOD | C10: Version Crue | D10: =COUNTIF(Brands!$A:$A,A10) -> 1 | E10: 1
A11: 10 | B11: AAPACK UG | C11: Spicywelt | D11: =COUNTIF(Brands!$A:$A,A11) -> 1 | E11: 1
A12: 11 | B12: Aarts Conserven BV | C12: Aarts | D12: =COUNTIF(Brands!$A:$A,A12) -> 1 | E12: 1
A13: 12 | B13: ABCD NUTRITION | C13: Ma boulangerie sans gluten | D13: =COUNTIF(Brands!$A:$A,A13) -> 1 | E13: 1
... A40: 39 | B40: Al Wadi Al Akhdar | C40: Al Wadi Al Akhdar | D40: =COUNTIF(Brands!$A:$A,A40) -> 1 | E40: 2
A41: 40 | B41: Aldi | C41: 25 marques concernées. Par exemple : Les Doris, Drizz, All seasons, Chevrefin, Conquérant, Swing, Golden bridge, Mr frites, Baccara, ADRIEN DELBOS, ALBONA, ARCHIPEL, ARIZONA, ASIA, GREEN, GARDEN, BELLE D'ALSACE, BERGER COMTOIS, BISTRO'VITE, Bon & Vég, BON-RI, BOUCHERIE St Clément, BOURG, BUTTELLA, CASA MORANDO, CHAMPRE, CHANTOISEAU, Château, CLAIRE ET LUCIE, CORRIL, CRACK'HOUR, CROC'MATIN, CROUSTI VOL, CRUST'OCEAN, D'ANTELLI, DELICATO, DELI'SALADES, MyVay, Mama Mancini, Westminster... | D41: =COUNTIF(Brands!$A:$A,A41) -> 40 | E41: 2 | F41: 3 legal entities (ALDI FR/PT/PL) listed in one row; Brand cell is not a real brand name or is a partial list - check; Brand list truncated in PDF ("...")
A42: 41 | B42: Aleksandra Ristic (E-commerce Shop) | C42: Aleksandra Ristic The Bio Foods | D42: =COUNTIF(Brands!$A:$A,A42) -> 1 | E42: 2
A43: 42 | B43: ALGA FOOD | C43: Julienne | D43: =COUNTIF(Brands!$A:$A,A43) -> 1 | E43: 2
A44: 43 | B44: Algorapolis | C44: Algorapolis | D44: =COUNTIF(Brands!$A:$A,A44) -> 1 | E44: 2
A45: 44 | B45: ALGROUPE | C45: ALGOOD | D45: =COUNTIF(Brands!$A:$A,A45) -> 1 | E45: 2
A46: 45 | B46: Alimentation Santé Collectivité | C46: Les Halles Solanid | D46: =COUNTIF(Brands!$A:$A,A46) -> 1 | E46: 2
A47: 46 | B47: ALISA | C47: Graines d'Alisa | D47: =COUNTIF(Brands!$A:$A,A47) -> 1 | E47: 2
A48: 47 | B48: ALL FREEZ NV | C48: All Freez | D48: =COUNTIF(Brands!$A:$A,A48) -> 1 | E48: 2
A49: 48 | B49: All Markets Europe | C49: Vita Coco | D49: =COUNTIF(Brands!$A:$A,A49) -> 1 | E49: 2
A50: 49 | B50: ALLIANCE OCEANE | C50: CORAYA | D50: =COUNTIF(Brands!$A:$A,A50) -> 1 | E50: 2
A51: 50 | B51: Allive Europe UAB | C51: Planet Superfood | D51: =COUNTIF(Brands!$A:$A,A51) -> 1 | E51: 2
A52: 51 | B52: Allmedica Arzneimittel GmbH | C52: Sheko | D52: =COUNTIF(Brands!$A:$A,A52) -> 1 | E52: 2
A53: 52 | B53: Alma & Valor, Lda. | C53: Iswari,Shine | D53: =COUNTIF(Brands!$A:$A,A53) -> 2 | E53: 2
... A81: 80 | B81: Aradi | C81: Aradi un moment de plaisir | D81: =COUNTIF(Brands!$A:$A,A81) -> 1 | E81: 3
A82: 81 | B82: ARC FOOD France | C82: No Name (produit commercialisé sans marque) | D82: =COUNTIF(Brands!$A:$A,A82) -> 1 | E82: 3 | F82: Brand cell is not a real brand name or is a partial list - check
A83: 82 | B83: ARCAL | C83: Prince de Bretagne | D83: =COUNTIF(Brands!$A:$A,A83) -> 1 | E83: 3
A84: 83 | B84: ARCHER Pascal | C84: respect des saveurs | D84: =COUNTIF(Brands!$A:$A,A84) -> 1 | E84: 3
A85: 84 | B85: ARCHIBALD GOURMET | C85: ARCHIBALD GOURMET | D85: =COUNTIF(Brands!$A:$A,A85) -> 1 | E85: 3
A86: 85 | B86: Argenta Schokoladenmanufaktur GmbH | C86: Doucer, GOURMET, Isaura | D86: =COUNTIF(Brands!$A:$A,A86) -> 3 | E86: 3
A87: 86 | B87: ARNAL SAS | C87: GRANVAL, SEBASTIEN DE KERDOUR, D'ARMOR & D'ARGOAT | D87: =COUNTIF(Brands!$A:$A,A87) -> 3 | E87: 3
A88: 87 | B88: ARRIVE S.A.S | C88: MAITRE COQ | D88: =COUNTIF(Brands!$A:$A,A88) -> 1 | E88: 3
A89: 88 | B89: ASSEMAN DEPREZ | C89: VIDELYS | D89: =COUNTIF(Brands!$A:$A,A89) -> 1 | E89: 3
A90: 89 | B90: association des agriculteurs du pays de Lorient | C90: BREIZH POSITIVE | D90: =COUNTIF(Brands!$A:$A,A90) -> 1 | E90: 3
A91: 90 | B91: ATELIER TECHNOLOGIQUE DE L'EPLEFPA DE SAINT-LÔ THERE | C91: LES ENFANTS THERIBLES | D91: =COUNTIF(Brands!$A:$A,A91) -> 1 | E91: 3
A92: 91 | B92: A-TEX | C92: LES DEUX PAGODES | D92: =COUNTIF(Brands!$A:$A,A92) -> 1 | E92: 3
A93: 92 | B93: Atlantique Alimentaire | C93: No name | D93: =COUNTIF(Brands!$A:$A,A93) -> 1 | E93: 3 | F93: Brand cell is not a real brand name or is a partial list - check
...

Sheet Brands
A1: Company ID | B1: Company | C1: Brand
A2: 1 | B2: 100% Ty'bigoud | C2: 100% Ty'bigoud
A3: 2 | B3: 110 GRAINES | C3: 110 Graines
A4: 3 | B4: 3615 soda | C4: Simple Vice
A5: 4 | B5: 4Retail | C5: Zagazoe
A6: 5 | B6: 4ULTRA | C6: 4ULTRA
A7: 6 | B7: 5M DEVELOPMENT | C7: STARTINE
A8: 7 | B8: 77 FOODS | C8: LA VIE
A9: 8 | B9: A&O L'EPICERIE LOCALE | C9: A&O
A10: 9 | B10: A.C.V. FOOD | C10: Version Crue
A11: 10 | B11: AAPACK UG | C11: Spicywelt
A12: 11 | B12: Aarts Conserven BV | C12: Aarts
A13: 12 | B13: ABCD NUTRITION | C13: Ma boulangerie sans gluten
... A1795: 1405 | B1795: ТОВ "ОРЕКС ДІСТРІБЬЮШЕН" | C1795: HLIBO
